Workbook

Sheet ALS 10 BAZAR
A1: PEDIDO DE COMPRA ALS 10 | J1: OBSERVAÇÕES:
A2: N° PEDIDO | E2: CONTATO | H2: DATA PEDIDO | I2: 46213 | J2: 37.144.240/0001-70 | R2: AGENDAR ENTREGA
A3: FORNECEDOR: | B3: VR VAROES | H3: DATA ENTREGA | I3: IMEDIATO | J3: als.conecta@gmail.com | R3: (42) 9 9136-5009
A4: VENDEDOR: | B4: RODRIGO | H4: % OFF | I4: 1 | J4: Rafael (55) 9. 9659-6315 | R4: DESCARREGAMENTO POR CONTA DO FORNECEDOR
A5: COND. PAG. | B5: BOLETO 30/45/60/75/90/105 | H5: PROGRAMAÇÃO | J5: Bruna (55) 9. 3618-5609
A6: REGIME | B6: PRESUMIDO
A7: ACRESCIMOS: | B7: FRETE | C7: CIF | D7: ST | E7: NÃO | F7: IPI | G7: NÃO | H7: DIFAL | I7: SIM
A8: REFERÊNCIA DE FÁBRICA | B8: DESCRIÇÃO PRODUTO | F8: QTD NO PEC | G8: QTD DE PEC | H8: QTD UNI | J8: VALOR TOTAL
B9: TOALHA EM METRO | F9: 30 | H9: =F9*G9 -> 0 | I9: 5.2 | J9: =H9*I9 -> 0
B10: TOALHA EM METRO TRANSPARENTE | F10: 30 | H10: =F10*G10 -> 0 | J10: =H10*I10 -> 0
B11: CORTINA BLACK OUT 1,40 X 1,00 | F11: 50 | H11: =F11*G11 -> 0 | I11: 7.5 | J11: =H11*I11 -> 0
B12: CORTINA DE BOX 1,80 X 1,20 | F12: 50 | H12: =F12*G12 -> 0 | J12: =H12*I12 -> 0
B13: CAPA MAQ. DE LAVAR 12/17KG | F13: 25 | H13: =F13*G13 -> 0 | I13: 7.5 | J13: =H13*I13 -> 0
B14: CAPA MAQ. DE LAVAR 7/11KG | F14: 25 | H14: =F14*G14 -> 0 | I14: 7.5 | J14: =H14*I14 -> 0
B15: VARAO DE CORTINA 1,5M BRANCO | F15: 10 | G15: 40 | H15: =F15*G15 -> 400 | I15: 5.6 | J15: =H15*I15 -> 2240
B16: VARAO DE CORTINA 2M BRANCO | F16: 10 | G16: 40 | H16: =F16*G16 -> 400 | I16: 6.5 | J16: =H16*I16 -> 2600
B17: VARAO DE CORTINA 2,5M BRANCO | F17: 10 | G17: 40 | H17: =F17*G17 -> 400 | I17: 7.6 | J17: =H17*I17 -> 3040
B18: VARAO DE CORTINA 1,5M IMBUIA | F18: 10 | G18: 40 | H18: =F18*G18 -> 400 | I18: 5.6 | J18: =H18*I18 -> 2240
B19: VARAO DE CORTINA 2M IMBUIA | F19: 10 | G19: 60 | H19: =F19*G19 -> 600 | I19: 6.5 | J19: =H19*I19 -> 3900
B20: VARAO DE CORTINA 2,5M IMBUIA | F20: 10 | G20: 40 | H20: =F20*G20 -> 400 | I20: 7.6 | J20: =H20*I20 -> 3040
B21: VARAO DE CORTINA 1,5M BEGE | F21: 10 | G21: 40 | H21: =F21*G21 -> 400 | I21: 5.6 | J21: =H21*I21 -> 2240
B22: VARAO DE CORTINA 2M BEGE | F22: 10 | G22: 40 | H22: =F22*G22 -> 400 | I22: 6.5 | J22: =H22*I22 -> 2600
B23: VARAO DE CORTINA 2,5M BEGE | F23: 10 | G23: 40 | H23: =F23*G23 -> 400 | I23: 7.6 | J23: =H23*I23 -> 3040
B24: VARAO 2M ROSA | F24: 10 | G24: 50 | H24: =F24*G24 -> 500 | I24: 6.5 | J24: =H24*I24 -> 3250
B25: VARAO 2M AZUL | F25: 10 | G25: 50 | H25: =F25*G25 -> 500 | I25: 6.5 | J25: =H25*I25 -> 3250
H26: =F26*G26 -> 0 | J26: =H26*I26 -> 0
H27: =F27*G27 -> 0 | J27: =H27*I27 -> 0
A28: PEDIDO FATURAR NO PRESUMIDO CREDITO DE 12% | H28: =F28*G28 -> 0 | J28: =H28*I28 -> 0
H29: =F29*G29 -> 0 | J29: =H29*I29 -> 0
H30: =F30*G30 -> 0 | J30: =H30*I30 -> 0
H31: =F31*G31 -> 0 | J31: =H31*I31 -> 0
A32: MANDAR 2 EXPOSITOR | H32: =F32*G32 -> 0 | J32: =H32*I32 -> 0
H33: =F33*G33 -> 0 | J33: =H33*I33 -> 0
H34: =F34*G34 -> 0 | J34: =H34*I34 -> 0
H35: =F35*G35 -> 0 | J35: =H35*I35 -> 0
H36: =F36*G36 -> 0 | J36: =H36*I36 -> 0
H37: =F37*G37 -> 0 | J37: =H37*I37 -> 0
H38: =F38*G38 -> 0 | J38: =H38*I38 -> 0
H39: =F39*G39 -> 0 | J39: =H39*I39 -> 0
H40: =F40*G40 -> 0 | J40: =H40*I40 -> 0
...

Sheet LIMITE DE PRECO
A1: PEDIDO DE COMPRA CONECTA | J1: OBSERVAÇÕES:
A2: N° PEDIDO | E2: CONTATO | H2: DATA PEDIDO | I2: ='ALS 10 BAZAR'!I2 -> 46213 | J2: 43.304.141/0001-00 | R2: AGENDAR ENTREGA
A3: FORNECEDOR: | B3: ='ALS 10 BAZAR'!B3:D3 -> VR VAROES | E3: ='ALS 10 BAZAR'!E3:G3 -> 0 | H3: DATA ENTREGA | I3: ='ALS 10 BAZAR'!I3 -> IMEDIATO | J3: als.conecta@gmail.com | R3: (42) 9 9136-5009
A4: VENDEDOR: | B4: ='ALS 10 BAZAR'!B4:D4 -> RODRIGO | E4: ='ALS 10 BAZAR'!E4:G4 -> 0 | H4: % OFF | I4: 0.33 | J4: Rafael (55) 9. 9659-6315 | R4: DESCARREGAMENTO POR CONTA DO FORNECEDOR
A5: COND. PAG. | B5: ='ALS 10 BAZAR'!B5:G5 -> BOLETO 30/45/60/75/90/105 | H5: PROGRAMAÇÃO | J5: Bruna (55) 9. 3618-5609
A6: OBSERVAÇÃO: | B6: BOLETOS E PEDIDOS VIA E-MAIL - PARTE ESPECIAL VIA DEPOSITOS | K6: ICMS | M6: IPI | O6: PIS/COFINS | Q6: FIXO | S6: TOTAL | U6: CREDITO ICMS | W6: PDV | Y6: VALOR DE COMPRA
A7: ACRESCIMOS: | B7: FRETE | C7: ='ALS 10 BAZAR'!C7 -> CIF | D7: ST | E7: ='ALS 10 BAZAR'!E7 -> NÃO | F7: IPI | G7: ='ALS 10 BAZAR'!G7 -> NÃO | H7: DIFAL | I7: ='ALS 10 BAZAR'!I7 -> SIM
A8: REFERÊNCIA DE FÁBRICA | B8: DESCRIÇÃO PRODUTO | F8: QTD NO PEC | G8: QTD DE PEC | H8: QTD UNI | J8: VALOR TOTAL | K8: 0.11 | M8: 0 | O8: 0.03 | Q8: 0.26 | S8: =SUM(K8:R8) -> 0.4 | U8: 0.195 | W8: 12 | Y8: 8
A9: ='ALS 10 BAZAR'!A9 -> 0 | B9: ='ALS 10 BAZAR'!B9:E9 -> TOALHA EM METRO | F9: ='ALS 10 BAZAR'!F9 -> 30 | G9: ='ALS 10 BAZAR'!G9 -> 0 | H9: =F9*G9 -> 0 | I9: ='ALS 10 BAZAR'!I9 -> 5.2 | J9: =H9*I9 -> 0
A10: ='ALS 10 BAZAR'!A10 -> 0 | B10: ='ALS 10 BAZAR'!B10:E10 -> TOALHA EM METRO TRANSPARENTE | F10: ='ALS 10 BAZAR'!F10 -> 30 | G10: ='ALS 10 BAZAR'!G10 -> 0 | H10: =F10*G10 -> 0 | I10: ='ALS 10 BAZAR'!I10 -> 0 | J10: =H10*I10 -> 0 | K10: DESPESAS | M10: VALOR CREDITO | O10: VALOR TOTAL PRODUTO
A11: ='ALS 10 BAZAR'!A11 -> 0 | B11: ='ALS 10 BAZAR'!B11:E11 -> CORTINA BLACK OUT 1,40 X 1,00 | F11: ='ALS 10 BAZAR'!F11 -> 50 | G11: ='ALS 10 BAZAR'!G11 -> 0 | H11: =F11*G11 -> 0 | I11: ='ALS 10 BAZAR'!I11 -> 7.5 | J11: =H11*I11 -> 0
A12: ='ALS 10 BAZAR'!A12 -> 0 | B12: ='ALS 10 BAZAR'!B12:E12 -> CORTINA DE BOX 1,80 X 1,20 | F12: ='ALS 10 BAZAR'!F12 -> 50 | G12: ='ALS 10 BAZAR'!G12 -> 0 | H12: =F12*G12 -> 0 | I12: ='ALS 10 BAZAR'!I12 -> 0 | J12: =H12*I12 -> 0 | K12: =W8*S8 -> 4.8 | M12: =Y8*U8 -> 1.56 | O12: =Y8+K12-M12 -> 11.24
A13: ='ALS 10 BAZAR'!A13 -> 0 | B13: ='ALS 10 BAZAR'!B13:E13 -> CAPA MAQ. DE LAVAR 12/17KG | F13: ='ALS 10 BAZAR'!F13 -> 25 | G13: ='ALS 10 BAZAR'!G13 -> 0 | H13: =F13*G13 -> 0 | I13: ='ALS 10 BAZAR'!I13 -> 7.5 | J13: =H13*I13 -> 0
A14: ='ALS 10 BAZAR'!A14 -> 0 | B14: ='ALS 10 BAZAR'!B14:E14 -> CAPA MAQ. DE LAVAR 7/11KG | F14: ='ALS 10 BAZAR'!F14 -> 25 | G14: ='ALS 10 BAZAR'!G14 -> 0 | H14: =F14*G14 -> 0 | I14: ='ALS 10 BAZAR'!I14 -> 7.5 | J14: =H14*I14 -> 0
A15: ='ALS 10 BAZAR'!A15 -> 0 | B15: ='ALS 10 BAZAR'!B15:E15 -> VARAO DE CORTINA 1,5M BRANCO | F15: ='ALS 10 BAZAR'!F15 -> 10 | G15: ='ALS 10 BAZAR'!G15 -> 40 | H15: =F15*G15 -> 400 | I15: ='ALS 10 BAZAR'!I15 -> 5.6 | J15: =H15*I15 -> 2240
A16: ='ALS 10 BAZAR'!A16 -> 0 | B16: ='ALS 10 BAZAR'!B16:E16 -> VARAO DE CORTINA 2M BRANCO | F16: ='ALS 10 BAZAR'!F16 -> 10 | G16: ='ALS 10 BAZAR'!G16 -> 40 | H16: =F16*G16 -> 400 | I16: ='ALS 10 BAZAR'!I16 -> 6.5 | J16: =H16*I16 -> 2600
A17: ='ALS 10 BAZAR'!A17 -> 0 | B17: ='ALS 10 BAZAR'!B17:E17 -> VARAO DE CORTINA 2,5M BRANCO | F17: ='ALS 10 BAZAR'!F17 -> 10 | G17: ='ALS 10 BAZAR'!G17 -> 40 | H17: =F17*G17 -> 400 | I17: ='ALS 10 BAZAR'!I17 -> 7.6 | J17: =H17*I17 -> 3040
A18: ='ALS 10 BAZAR'!A18 -> 0 | B18: ='ALS 10 BAZAR'!B18:E18 -> VARAO DE CORTINA 1,5M IMBUIA | F18: ='ALS 10 BAZAR'!F18 -> 10 | G18: ='ALS 10 BAZAR'!G18 -> 40 | H18: =F18*G18 -> 400 | I18: ='ALS 10 BAZAR'!I18 -> 5.6 | J18: =H18*I18 -> 2240
A19: ='ALS 10 BAZAR'!A19 -> 0 | B19: ='ALS 10 BAZAR'!B19:E19 -> VARAO DE CORTINA 2M IMBUIA | F19: ='ALS 10 BAZAR'!F19 -> 10 | G19: ='ALS 10 BAZAR'!G19 -> 60 | H19: =F19*G19 -> 600 | I19: ='ALS 10 BAZAR'!I19 -> 6.5 | J19: =H19*I19 -> 3900
A20: ='ALS 10 BAZAR'!A20 -> 0 | B20: ='ALS 10 BAZAR'!B20:E20 -> VARAO DE CORTINA 2,5M IMBUIA | F20: ='ALS 10 BAZAR'!F20 -> 10 | G20: ='ALS 10 BAZAR'!G20 -> 40 | H20: =F20*G20 -> 400 | I20: ='ALS 10 BAZAR'!I20 -> 7.6 | J20: =H20*I20 -> 3040
A21: ='ALS 10 BAZAR'!A21 -> 0 | B21: ='ALS 10 BAZAR'!B21:E21 -> VARAO DE CORTINA 1,5M BEGE | F21: ='ALS 10 BAZAR'!F21 -> 10 | G21: ='ALS 10 BAZAR'!G21 -> 40 | H21: =F21*G21 -> 400 | I21: ='ALS 10 BAZAR'!I21 -> 5.6 | J21: =H21*I21 -> 2240
A22: ='ALS 10 BAZAR'!A22 -> 0 | B22: ='ALS 10 BAZAR'!B22:E22 -> VARAO DE CORTINA 2M BEGE | F22: ='ALS 10 BAZAR'!F22 -> 10 | G22: ='ALS 10 BAZAR'!G22 -> 40 | H22: =F22*G22 -> 400 | I22: ='ALS 10 BAZAR'!I22 -> 6.5 | J22: =H22*I22 -> 2600
A23: ='ALS 10 BAZAR'!A23 -> 0 | B23: ='ALS 10 BAZAR'!B23:E23 -> VARAO DE CORTINA 2,5M BEGE | F23: ='ALS 10 BAZAR'!F23 -> 10 | G23: ='ALS 10 BAZAR'!G23 -> 40 | H23: =F23*G23 -> 400 | I23: ='ALS 10 BAZAR'!I23 -> 7.6 | J23: =H23*I23 -> 3040
A24: ='ALS 10 BAZAR'!A24 -> 0 | B24: ='ALS 10 BAZAR'!B24:E24 -> VARAO 2M ROSA | F24: ='ALS 10 BAZAR'!F24 -> 10 | G24: ='ALS 10 BAZAR'!G24 -> 50 | H24: =F24*G24 -> 500 | I24: ='ALS 10 BAZAR'!I24 -> 6.5 | J24: =H24*I24 -> 3250
... A68: ='ALS 10 BAZAR'!A68 -> 0 | B68: ='ALS 10 BAZAR'!B68:E68 -> 0 | F68: ='ALS 10 BAZAR'!F68 -> 0 | G68: ='ALS 10 BAZAR'!G68 -> 0 | H68: =F68*G68 -> 0 | I68: ='ALS 10 BAZAR'!I68 -> 0 | J68: =H68*I68 -> 0
A69: ='ALS 10 BAZAR'!A68 -> 0 | B69: ='ALS 10 BAZAR'!B68:E68 -> 0 | F69: ='ALS 10 BAZAR'!F68 -> 0 | G69: ='ALS 10 BAZAR'!G68 -> 0 | H69: =F69*G69 -> 0 | I69: ='ALS 10 BAZAR'!I68 -> 0 | J69: =H69*I69 -> 0
A70: ='ALS 10 BAZAR'!A69 -> 0 | B70: ='ALS 10 BAZAR'!B69:E69 -> 0 | F70: ='ALS 10 BAZAR'!F69 -> 0 | G70: ='ALS 10 BAZAR'!G69 -> 0 | H70: =F70*G70 -> 0 | I70: ='ALS 10 BAZAR'!I69 -> 0 | J70: =H70*I70 -> 0
A71: ='ALS 10 BAZAR'!A70 -> 0 | B71: ='ALS 10 BAZAR'!B70:E70 -> 0 | F71: ='ALS 10 BAZAR'!F70 -> 0 | G71: ='ALS 10 BAZAR'!G70 -> 0 | H71: =F71*G71 -> 0 | I71: ='ALS 10 BAZAR'!I70 -> 0 | J71: =H71*I71 -> 0
A72: CONFERENTE | H72: =F72*G72 -> 0 | J72: =H72*I72 -> 0
H73: =F73*G73 -> 0 | J73: =H73*I73 -> 0
A74: POSSUI AVARIAS? | B74: SIM | D74: NÃO | H74: =F74*G74 -> 0 | J74: =H74*I74 -> 0
H75: =F75*G75 -> 0 | J75: =H75*I75 -> 0
A76: **SE POSSUIR AVARIAS APONTAR NO VERSO DA FOLHA | H76: =F76*G76 -> 0 | J76: =H76*I76 -> 0
G77: =SUM(G9:G76) -> 480 | H77: =SUM(H9:H76) -> 4800 | J77: =SUM(J9:J76) -> 31440 | N77: VALOR TOTAL
A78: PREÇO MÉDIO | I78: =SUMIF(I9:I76,">0",J9:J76)/(SUMIF(I9:I76,">0",H9:H76)) -> 6.55 | J78: =H77 -> 4800

Sheet SEPARACAO
A1: PEDIDO PARA SEPARACAO
A2: N° PEDIDO | E2: CONTATO | H2: PEDIDO | I2: ='ALS 10 BAZAR'!I2 -> 46213
A3: FORNECEDOR: | B3: ='ALS 10 BAZAR'!B3:D3 -> VR VAROES | H3: RECEBIMENTO | I3: ='ALS 10 BAZAR'!I3 -> IMEDIATO
A4: VENDEDOR: | B4: ='ALS 10 BAZAR'!B4:D4 -> RODRIGO | H4: % OFF | I4: ='ALS 10 BAZAR'!I4 -> 1
A5: COND. PAG. | B5: ='ALS 10 BAZAR'!B5:G5 -> BOLETO 30/45/60/75/90/105 | H5: PROG. | I5: ='ALS 10 BAZAR'!I5 -> 0
A6: OBSERVAÇÃO: | K6: A | AA6: B | AQ6: C
A7: ACRESCIMOS: | B7: FRETE | C7: ='ALS 10 BAZAR'!C7 -> CIF | D7: ST | E7: ='ALS 10 BAZAR'!E7 -> NÃO | F7: IPI | G7: ='ALS 10 BAZAR'!G7 -> NÃO | H7: DIFAL | I7: ='ALS 10 BAZAR'!I7 -> SIM
A8: REFERÊNCIA DE FÁBRICA | B8: DESCRIÇÃO PRODUTO | F8: QTD NO PEC | G8: QTD DE PEC | H8: QTD UNI | I8: CODIGO INTERNO | J8: PDV | K8: P.G CENTRO | M8: RESERVA | O8: TIBAGI | Q8: N. RUSSIA | S8: JAVERT | U8: IVAI | W8: IRATI C. | Y8: CAMPO LARGO | AA8: CASTRO | AC8: IMBITUVA | AE8: SANTA PAULA | AG8: PRUDE | AI8: GUARAPUAVA | AK8: IMBAU | AM8: RIO AZUL | AO8: REBOUCAS | AQ8: DEPOSITO | AS8: TEIXEIRA | AU8: MALLET | AW8: IPIRANGA
A9: ='ALS 10 BAZAR'!A9 -> 0 | B9: ='ALS 10 BAZAR'!B9:E9 -> TOALHA EM METRO | F9: ='ALS 10 BAZAR'!F9 -> 30 | G9: ='ALS 10 BAZAR'!G9 -> 0 | H9: =F9*G9 -> 0 | K9: 10
A10: ='ALS 10 BAZAR'!A10 -> 0 | B10: ='ALS 10 BAZAR'!B10:E10 -> TOALHA EM METRO TRANSPARENTE | F10: ='ALS 10 BAZAR'!F10 -> 30 | G10: ='ALS 10 BAZAR'!G10 -> 0 | H10: =F10*G10 -> 0
A11: ='ALS 10 BAZAR'!A11 -> 0 | B11: ='ALS 10 BAZAR'!B11:E11 -> CORTINA BLACK OUT 1,40 X 1,00 | F11: ='ALS 10 BAZAR'!F11 -> 50 | G11: ='ALS 10 BAZAR'!G11 -> 0 | H11: =F11*G11 -> 0
A12: ='ALS 10 BAZAR'!A12 -> 0 | B12: ='ALS 10 BAZAR'!B12:E12 -> CORTINA DE BOX 1,80 X 1,20 | F12: ='ALS 10 BAZAR'!F12 -> 50 | G12: ='ALS 10 BAZAR'!G12 -> 0 | H12: =F12*G12 -> 0
A13: ='ALS 10 BAZAR'!A13 -> 0 | B13: ='ALS 10 BAZAR'!B13:E13 -> CAPA MAQ. DE LAVAR 12/17KG | F13: ='ALS 10 BAZAR'!F13 -> 25 | G13: ='ALS 10 BAZAR'!G13 -> 0 | H13: =F13*G13 -> 0
A14: ='ALS 10 BAZAR'!A14 -> 0 | B14: ='ALS 10 BAZAR'!B14:E14 -> CAPA MAQ. DE LAVAR 7/11KG | F14: ='ALS 10 BAZAR'!F14 -> 25 | G14: ='ALS 10 BAZAR'!G14 -> 0 | H14: =F14*G14 -> 0
A15: ='ALS 10 BAZAR'!A15 -> 0 | B15: ='ALS 10 BAZAR'!B15:E15 -> VARAO DE CORTINA 1,5M BRANCO | F15: ='ALS 10 BAZAR'!F15 -> 10 | G15: ='ALS 10 BAZAR'!G15 -> 40 | H15: =F15*G15 -> 400 | K15: 3
A16: ='ALS 10 BAZAR'!A16 -> 0 | B16: ='ALS 10 BAZAR'!B16:E16 -> VARAO DE CORTINA 2M BRANCO | F16: ='ALS 10 BAZAR'!F16 -> 10 | G16: ='ALS 10 BAZAR'!G16 -> 40 | H16: =F16*G16 -> 400 | K16: 5
A17: ='ALS 10 BAZAR'!A17 -> 0 | B17: ='ALS 10 BAZAR'!B17:E17 -> VARAO DE CORTINA 2,5M BRANCO | F17: ='ALS 10 BAZAR'!F17 -> 10 | G17: ='ALS 10 BAZAR'!G17 -> 40 | H17: =F17*G17 -> 400 | K17: 3
A18: ='ALS 10 BAZAR'!A18 -> 0 | B18: ='ALS 10 BAZAR'!B18:E18 -> VARAO DE CORTINA 1,5M IMBUIA | F18: ='ALS 10 BAZAR'!F18 -> 10 | G18: ='ALS 10 BAZAR'!G18 -> 40 | H18: =F18*G18 -> 400 | K18: 3
A19: ='ALS 10 BAZAR'!A19 -> 0 | B19: ='ALS 10 BAZAR'!B19:E19 -> VARAO DE CORTINA 2M IMBUIA | F19: ='ALS 10 BAZAR'!F19 -> 10 | G19: ='ALS 10 BAZAR'!G19 -> 60 | H19: =F19*G19 -> 600 | K19: 2
A20: ='ALS 10 BAZAR'!A20 -> 0 | B20: ='ALS 10 BAZAR'!B20:E20 -> VARAO DE CORTINA 2,5M IMBUIA | F20: ='ALS 10 BAZAR'!F20 -> 10 | G20: ='ALS 10 BAZAR'!G20 -> 40 | H20: =F20*G20 -> 400 | K20: 2
A21: ='ALS 10 BAZAR'!A21 -> 0 | B21: ='ALS 10 BAZAR'!B21:E21 -> VARAO DE CORTINA 1,5M BEGE | F21: ='ALS 10 BAZAR'!F21 -> 10 | G21: ='ALS 10 BAZAR'!G21 -> 40 | H21: =F21*G21 -> 400 | K21: 2
A22: ='ALS 10 BAZAR'!A22 -> 0 | B22: ='ALS 10 BAZAR'!B22:E22 -> VARAO DE CORTINA 2M BEGE | F22: ='ALS 10 BAZAR'!F22 -> 10 | G22: ='ALS 10 BAZAR'!G22 -> 40 | H22: =F22*G22 -> 400 | K22: 3
A23: ='ALS 10 BAZAR'!A23 -> 0 | B23: ='ALS 10 BAZAR'!B23:E23 -> VARAO DE CORTINA 2,5M BEGE | F23: ='ALS 10 BAZAR'!F23 -> 10 | G23: ='ALS 10 BAZAR'!G23 -> 40 | H23: =F23*G23 -> 400 | K23: 2
A24: ='ALS 10 BAZAR'!A24 -> 0 | B24: ='ALS 10 BAZAR'!B24:E24 -> VARAO 2M ROSA | F24: ='ALS 10 BAZAR'!F24 -> 10 | G24: ='ALS 10 BAZAR'!G24 -> 50 | H24: =F24*G24 -> 500 | K24: 1
A25: ='ALS 10 BAZAR'!A25 -> 0 | B25: ='ALS 10 BAZAR'!B25:E25 -> VARAO 2M AZUL | F25: ='ALS 10 BAZAR'!F25 -> 10 | G25: ='ALS 10 BAZAR'!G25 -> 50 | H25: =F25*G25 -> 500 | K25: 1
A26: ='ALS 10 BAZAR'!A26 -> 0 | B26: ='ALS 10 BAZAR'!B26:E26 -> 0 | F26: ='ALS 10 BAZAR'!F26 -> 0 | G26: ='ALS 10 BAZAR'!G26 -> 0 | H26: =F26*G26 -> 0
A27: ='ALS 10 BAZAR'!A27 -> 0 | B27: ='ALS 10 BAZAR'!B27:E27 -> 0 | F27: ='ALS 10 BAZAR'!F27 -> 0 | G27: ='ALS 10 BAZAR'!G27 -> 0 | H27: =F27*G27 -> 0
A28: PEDIDO FATURAR NO PRESUMIDO CREDITO DE 12% | H28: =F28*G28 -> 0
H29: =F29*G29 -> 0
H30: =F30*G30 -> 0
H31: =F31*G31 -> 0
A32: MANDAR SEM FALTA 1 EXPOSITOR DE TOALHAS COM CORTE E 1 DE VARAO | H32: =F32*G32 -> 0
H33: =F33*G33 -> 0
H34: =F34*G34 -> 0
A35: ='ALS 10 BAZAR'!A35 -> 0 | B35: ='ALS 10 BAZAR'!B35:E35 -> 0 | F35: ='ALS 10 BAZAR'!F35 -> 0 | G35: ='ALS 10 BAZAR'!G35 -> 0 | H35: =F35*G35 -> 0
A36: ='ALS 10 BAZAR'!A36 -> 0 | B36: ='ALS 10 BAZAR'!B36:E36 -> 0 | F36: ='ALS 10 BAZAR'!F36 -> 0 | G36: ='ALS 10 BAZAR'!G36 -> 0 | H36: =F36*G36 -> 0
A37: ='ALS 10 BAZAR'!A37 -> 0 | B37: ='ALS 10 BAZAR'!B37:E37 -> 0 | F37: ='ALS 10 BAZAR'!F37 -> 0 | G37: ='ALS 10 BAZAR'!G37 -> 0 | H37: =F37*G37 -> 0
A38: ='ALS 10 BAZAR'!A38 -> 0 | B38: ='ALS 10 BAZAR'!B38:E38 -> 0 | F38: ='ALS 10 BAZAR'!F38 -> 0 | G38: ='ALS 10 BAZAR'!G38 -> 0 | H38: =F38*G38 -> 0
A39: ='ALS 10 BAZAR'!A39 -> 0 | B39: ='ALS 10 BAZAR'!B39:E39 -> 0 | F39: ='ALS 10 BAZAR'!F39 -> 0 | G39: ='ALS 10 BAZAR'!G39 -> 0 | H39: =F39*G39 -> 0
A40: ='ALS 10 BAZAR'!A40 -> 0 | B40: ='ALS 10 BAZAR'!B40:E40 -> 0 | F40: ='ALS 10 BAZAR'!F40 -> 0 | G40: ='ALS 10 BAZAR'!G40 -> 0 | H40: =F40*G40 -> 0
...

Sheet CALCULADORA
A1: CALCULADORA DA SEPARACAO
A2: QUANTIDADE | B2: 2.5 | C2: 1.75 | D2: 1.25 | E2: 39
B4: 8 | C4: 8 | D4: 4
B5: =SUM(B4*B2) -> 20 | C5: =SUM(C4*C2) -> 14 | D5: =SUM(D4*D2) -> 5
B6: =A3/E2*B5 -> 0 | C6: =A3/E2*C5 -> 0 | D6: =A3/E2*D5 -> 0
B7: A | C7: B | D7: C | E7: TOTAL
A8: SEPARACAO | B8: =B6/B4 -> 0 | C8: =C6/C4 -> 0 | D8: =D6/D4 -> 0 | E8: =SUM(B6:D6) -> 0
